Workbook

Sheet Chart of Accounts
A1: CHART OF ACCOUNTS
A3: Code | B3: Account name | C3: Type
A4: 1000 | B4: Bank | C4: Asset
A5: 1010 | B5: Cash | C5: Asset
A6: 1100 | B6: Inventory | C6: Asset
A7: 1200 | B7: Equipment | C7: Asset
A8: 2000 | B8: Trade Creditors | C8: Liability
A9: 2100 | B9: Bank Loan | C9: Liability
A10: 3000 | B10: Owner's Capital | C10: Equity
A11: 3100 | B11: Drawings | C11: Equity
A12: 4000 | B12: Sales | C12: Income
A13: 5000 | B13: Purchases | C13: Expense
A14: 5100 | B14: Rent | C14: Expense
A15: 5200 | B15: Wages | C15: Expense
... A19: 5600 | B19: Sundry Expenses | C19: Expense

Sheet Transactions
A1: TRANSACTIONS - what happened (post these on the Journal tab)
A3: T# | B3: Date | C3: Description | D3: Amount
A4: T1 | B4: 02 Jan | C4: Owner pays 12,000 of personal savings into the business bank account (capital introduced). | D4: 12000
A5: T2 | B5: 03 Jan | C5: Buys a commercial espresso machine and equipment, paid by bank transfer. | D5: 4000
A6: T3 | B6: 05 Jan | C6: Receives a 6,000 bank loan into the business bank account. | D6: 6000
A7: T4 | B7: 06 Jan | C7: Pays January shop rent by bank. | D7: 900
A8: T5 | B8: 07 Jan | C8: Buys coffee beans, milk and supplies (stock), paid by bank. | D8: 1100
A9: T6 | B9: 10 Jan | C9: Buys shop fittings and furniture (equipment), paid by bank. | D9: 1800
A10: T7 | B10: 15 Jan | C10: Cash sales for the first half of January, banked. | D10: 2300
A11: T8 | B11: 20 Jan | C11: Pays for marketing flyers, by bank. | D11: 150
A12: T9 | B12: 28 Jan | C12: Pays part-time barista wages, by bank. | D12: 1200
A13: T10 | B13: 31 Jan | C13: Cash sales for the second half of January, banked. | D13: 2800
A14: T11 | B14: 31 Jan | C14: Pays January electricity and water, by bank. | D14: 240
A15: T12 | B15: 02 Feb | C15: Buys more stock (beans, milk, cups), paid by bank. | D15: 1300
... A30: T27 | B30: 31 Mar | C30: Pays March utilities, by bank. | D30: 250

Sheet Journal
A1: GENERAL JOURNAL - post every transaction here (equal debits and credits)
A2: First 3 are worked examples. Pick the Account from the dropdown. Each transaction's debits must equal its credits.
A4: T# | B4: Date | C4: Description | D4: Account | E4: Debit | F4: Credit
A5: T1 | B5: 02 Jan | C5: Capital introduced | D5: Bank | E5: 12000
A6: T1 | B6: 02 Jan | C6: Capital introduced | D6: Owner's Capital | F6: 12000
A7: T2 | B7: 03 Jan | C7: Espresso machine / equipment | D7: Equipment | E7: 4000
A8: T2 | B8: 03 Jan | C8: Espresso machine / equipment | D8: Bank | F8: 4000
A9: T3 | B9: 05 Jan | C9: Bank loan received | D9: Bank | E9: 6000
A10: T3 | B10: 05 Jan | C10: Bank loan received | D10: Bank Loan | F10: 6000
A11: ="T"&(4+INT((ROW()-11)/2)) -> T4 | B11: 06 Jan | C11: Jan shop rent | D11: Rent | E11: 900
A12: ="T"&(4+INT((ROW()-11)/2)) -> T4 | B12: 06 Jan | C12: Jan shop rent | D12: Bank | F12: 900
A13: ="T"&(4+INT((ROW()-11)/2)) -> T5 | B13: 07 Jan | C13: Stock purchased | D13: Purchases | E13: 1100
A14: ="T"&(4+INT((ROW()-11)/2)) -> T5 | B14: 07 Jan | C14: Stock purchased | D14: Bank | F14: 1100
A15: ="T"&(4+INT((ROW()-11)/2)) -> T6 | B15: 46032 | C15: Furniture / equipment | D15: Equipment | E15: 1800
A16: ="T"&(4+INT((ROW()-11)/2)) -> T6 | B16: 46032 | C16: Furniture / equipment | D16: Bank | F16: 1800
A17: ="T"&(4+INT((ROW()-11)/2)) -> T7 | B17: 15 Jan | C17: Cash sales banked | D17: Bank | E17: 2300
A18: ="T"&(4+INT((ROW()-11)/2)) -> T7 | B18: 15 Jan | C18: Cash sales banked | D18: Sales | F18: 2300
A19: ="T"&(4+INT((ROW()-11)/2)) -> T8 | B19: 20 Jan | C19: Marketing | D19: Marketing | E19: 150
A20: ="T"&(4+INT((ROW()-11)/2)) -> T8 | B20: 20 Jan | C20: Marketing | D20: Bank | F20: 150
A21: ="T"&(4+INT((ROW()-11)/2)) -> T9 | B21: 28 Jan | C21: Part time wages | D21: Wages | E21: 1200
A22: ="T"&(4+INT((ROW()-11)/2)) -> T9 | B22: 28 Jan | C22: Part time wages | D22: Bank | F22: 1200
A23: ="T"&(4+INT((ROW()-11)/2)) -> T10 | B23: 31 Jan | C23: Cash sales banked | D23: Bank | E23: 2800
A24: ="T"&(4+INT((ROW()-11)/2)) -> T10 | B24: 31 Jan | C24: Cash sales banked | D24: Sales | F24: 2800
A25: ="T"&(4+INT((ROW()-11)/2)) -> T11 | B25: 31 Jan | C25: Jan utility Bills | D25: Utilities | E25: 240
A26: ="T"&(4+INT((ROW()-11)/2)) -> T11 | B26: 31 Jan | C26: Jan utility Bills | D26: Bank | F26: 240
A27: ="T"&(4+INT((ROW()-11)/2)) -> T12 | B27: 02 Feb | C27: Stock purchased | D27: Purchases | E27: 1300
A28: ="T"&(4+INT((ROW()-11)/2)) -> T12 | B28: 46055 | C28: Stock purchased | D28: Bank | F28: 1300
A29: ="T"&(4+INT((ROW()-11)/2)) -> T13 | B29: 05 Feb | C29: Feb shop rent | D29: Rent | E29: 900
A30: ="T"&(4+INT((ROW()-11)/2)) -> T13 | B30: 05 Feb | C30: Feb shop rent | D30: Bank | F30: 900
A31: ="T"&(4+INT((ROW()-11)/2)) -> T14 | B31: 12 Feb | C31: Stock purchased on credit | D31: Purchases | E31: 900
A32: ="T"&(4+INT((ROW()-11)/2)) -> T14 | B32: 12 Feb | C32: Stock purchased on credit | D32: Trade Creditors | F32: 900
A33: ="T"&(4+INT((ROW()-11)/2)) -> T15 | B33: 18 Feb | C33: Cash sales banked | D33: Bank | E33: 3100
A34: ="T"&(4+INT((ROW()-11)/2)) -> T15 | B34: 18 Feb | C34: Cash sales banked | D34: Sales | F34: 3100
A35: ="T"&(4+INT((ROW()-11)/2)) -> T16 | B35: 25 Feb | C35: Wages | D35: Wages | E35: 1250
A36: ="T"&(4+INT((ROW()-11)/2)) -> T16 | B36: 25 Feb | C36: Wages | D36: Bank | F36: 1250
A37: ="T"&(4+INT((ROW()-11)/2)) -> T17 | B37: 26 Feb | C37: Paid stock purchase credit | D37: Trade Creditors | E37: 900
A38: ="T"&(4+INT((ROW()-11)/2)) -> T17 | B38: 26 Feb | C38: Paid stock purchase credit | D38: Bank | F38: 900
A39: ="T"&(4+INT((ROW()-11)/2)) -> T18 | B39: 28 Feb | C39: Drawings | D39: Drawings | E39: 800
A40: ="T"&(4+INT((ROW()-11)/2)) -> T18 | B40: 28 Feb | C40: Drawings | D40: Bank | F40: 800
A41: ="T"&(4+INT((ROW()-11)/2)) -> T19 | B41: 28 Feb | C41: Feb utility Bills | D41: Utilities | E41: 260
...

Sheet Trial Balance
A1: TRIAL BALANCE (fills automatically from the Journal)
A3: Account | B3: Debit | C3: Credit
A4: Bank | B4: =MAX(0,SUMIF(Journal!$D:$D,A4,Journal!$E:$E)-SUMIF(Journal!$D:$D,A4,Journal!$F:$F)) -> 12725 | C4: =MAX(0,SUMIF(Journal!$D:$D,A4,Journal!$F:$F)-SUMIF(Journal!$D:$D,A4,Journal!$E:$E)) -> 0
A5: Cash | B5: =MAX(0,SUMIF(Journal!$D:$D,A5,Journal!$E:$E)-SUMIF(Journal!$D:$D,A5,Journal!$F:$F)) -> 0 | C5: =MAX(0,SUMIF(Journal!$D:$D,A5,Journal!$F:$F)-SUMIF(Journal!$D:$D,A5,Journal!$E:$E)) -> 0
A6: Inventory | B6: =MAX(0,SUMIF(Journal!$D:$D,A6,Journal!$E:$E)-SUMIF(Journal!$D:$D,A6,Journal!$F:$F)) -> 0 | C6: =MAX(0,SUMIF(Journal!$D:$D,A6,Journal!$F:$F)-SUMIF(Journal!$D:$D,A6,Journal!$E:$E)) -> 0
A7: Equipment | B7: =MAX(0,SUMIF(Journal!$D:$D,A7,Journal!$E:$E)-SUMIF(Journal!$D:$D,A7,Journal!$F:$F)) -> 5800 | C7: =MAX(0,SUMIF(Journal!$D:$D,A7,Journal!$F:$F)-SUMIF(Journal!$D:$D,A7,Journal!$E:$E)) -> 0
A8: Trade Creditors | B8: =MAX(0,SUMIF(Journal!$D:$D,A8,Journal!$E:$E)-SUMIF(Journal!$D:$D,A8,Journal!$F:$F)) -> 0 | C8: =MAX(0,SUMIF(Journal!$D:$D,A8,Journal!$F:$F)-SUMIF(Journal!$D:$D,A8,Journal!$E:$E)) -> 0
A9: Bank Loan | B9: =MAX(0,SUMIF(Journal!$D:$D,A9,Journal!$E:$E)-SUMIF(Journal!$D:$D,A9,Journal!$F:$F)) -> 0 | C9: =MAX(0,SUMIF(Journal!$D:$D,A9,Journal!$F:$F)-SUMIF(Journal!$D:$D,A9,Journal!$E:$E)) -> 5500
A10: Owner's Capital | B10: =MAX(0,SUMIF(Journal!$D:$D,A10,Journal!$E:$E)-SUMIF(Journal!$D:$D,A10,Journal!$F:$F)) -> 0 | C10: =MAX(0,SUMIF(Journal!$D:$D,A10,Journal!$F:$F)-SUMIF(Journal!$D:$D,A10,Journal!$E:$E)) -> 12000
A11: Drawings | B11: =MAX(0,SUMIF(Journal!$D:$D,A11,Journal!$E:$E)-SUMIF(Journal!$D:$D,A11,Journal!$F:$F)) -> 800 | C11: =MAX(0,SUMIF(Journal!$D:$D,A11,Journal!$F:$F)-SUMIF(Journal!$D:$D,A11,Journal!$E:$E)) -> 0
A12: Sales | B12: =MAX(0,SUMIF(Journal!$D:$D,A12,Journal!$E:$E)-SUMIF(Journal!$D:$D,A12,Journal!$F:$F)) -> 0 | C12: =MAX(0,SUMIF(Journal!$D:$D,A12,Journal!$F:$F)-SUMIF(Journal!$D:$D,A12,Journal!$E:$E)) -> 14500
A13: Purchases | B13: =MAX(0,SUMIF(Journal!$D:$D,A13,Journal!$E:$E)-SUMIF(Journal!$D:$D,A13,Journal!$F:$F)) -> 4700 | C13: =MAX(0,SUMIF(Journal!$D:$D,A13,Journal!$F:$F)-SUMIF(Journal!$D:$D,A13,Journal!$E:$E)) -> 0
A14: Rent | B14: =MAX(0,SUMIF(Journal!$D:$D,A14,Journal!$E:$E)-SUMIF(Journal!$D:$D,A14,Journal!$F:$F)) -> 2700 | C14: =MAX(0,SUMIF(Journal!$D:$D,A14,Journal!$F:$F)-SUMIF(Journal!$D:$D,A14,Journal!$E:$E)) -> 0
A15: Wages | B15: =MAX(0,SUMIF(Journal!$D:$D,A15,Journal!$E:$E)-SUMIF(Journal!$D:$D,A15,Journal!$F:$F)) -> 3750 | C15: =MAX(0,SUMIF(Journal!$D:$D,A15,Journal!$F:$F)-SUMIF(Journal!$D:$D,A15,Journal!$E:$E)) -> 0
... A19: Sundry Expenses | B19: =MAX(0,SUMIF(Journal!$D:$D,A19,Journal!$E:$E)-SUMIF(Journal!$D:$D,A19,Journal!$F:$F)) -> 25 | C19: =MAX(0,SUMIF(Journal!$D:$D,A19,Journal!$F:$F)-SUMIF(Journal!$D:$D,A19,Journal!$E:$E)) -> 0
A20: TOTAL | B20: =SUM(B4:B19) -> 32000 | C20: =SUM(C4:C19) -> 32000
A22: Balanced? | B22: =IF(B20=C20,"YES - balanced","NO - check journal") -> YES - balanced

Sheet P&L and Balance Sheet
A1: PROFIT & LOSS and BALANCE SHEET (fill automatically)
A3: PROFIT & LOSS (Quarter) | D3: BALANCE SHEET (as at 31 Mar)
A4: Sales | B4: =-('Trial Balance'!B12-'Trial Balance'!C12) -> 14500 | D4: ASSETS
A5: Less: Purchases | B5: =('Trial Balance'!B13-'Trial Balance'!C13) -> 4700 | D5: Equipment | E5: =('Trial Balance'!B7-'Trial Balance'!C7) -> 5800
A6: Less: Rent | B6: =('Trial Balance'!B14-'Trial Balance'!C14) -> 2700 | D6: Inventory | E6: =('Trial Balance'!B6-'Trial Balance'!C6) -> 0
A7: Less: Wages | B7: =('Trial Balance'!B15-'Trial Balance'!C15) -> 3750 | D7: Bank | E7: =('Trial Balance'!B4-'Trial Balance'!C4) -> 12725
A8: Less: Utilities | B8: =('Trial Balance'!B16-'Trial Balance'!C16) -> 750 | D8: Cash | E8: =('Trial Balance'!B5-'Trial Balance'!C5) -> 0
A9: Less: Insurance | B9: =('Trial Balance'!B17-'Trial Balance'!C17) -> 600 | D9: Total assets | E9: =SUM(E5:E8) -> 18525
A10: Less: Marketing | B10: =('Trial Balance'!B18-'Trial Balance'!C18) -> 150 | D10: LIABILITIES
A11: Less: Sundry Expenses | B11: =('Trial Balance'!B19-'Trial Balance'!C19) -> 25 | D11: Trade Creditors | E11: =-('Trial Balance'!B8-'Trial Balance'!C8) -> 0
A12: NET PROFIT | B12: =B4-SUM(B5:B11) -> 1825 | D12: Bank Loan | E12: =-('Trial Balance'!B9-'Trial Balance'!C9) -> 5500
D13: Total liabilities | E13: =SUM(E11:E12) -> 5500
D14: NET ASSETS | E14: =E9-E13 -> 13025
D15: FINANCED BY
D16: Owner's Capital | E16: =-('Trial Balance'!B10-'Trial Balance'!C10) -> 12000
D17: Add: Net profit | E17: =B12 -> 1825
D18: Less: Drawings | E18: =-('Trial Balance'!B11-'Trial Balance'!C11) -> -800
D19: Total equity | E19: =SUM(E16:E18) -> 13025
D21: Check: Net assets = Total equity? | E21: =IF(E14=E19,"YES","NO") -> YES

Sheet Bank Reconciliation
A1: BANK RECONCILIATION (as at 31 Mar 2026)
A2: Agree your Bank ledger balance to the bank statement. Fill the yellow cell.
A4: Bank statement closing balance (given by the bank): | B4: 9825
A6: Add: 31 Mar cash sales banked but not yet on the statement (deposit in transit): | B6: 2900
A8: Adjusted bank statement balance (statement + deposit in transit): | B8: =B4+B6 -> 12725
A10: Your Bank ledger balance (from Trial Balance, AFTER you post the 25 bank charge): | B10: ='Trial Balance'!B4-'Trial Balance'!C4 -> 12725
A12: Do they agree? | B12: =IF(B8=B10,"YES - reconciled","Not yet") -> YES - reconciled
A14: The 25 bank charge is a cash-book adjustment: it is already on the statement, so post it in the Journal
A15: (Debit Sundry Expenses, Credit Bank). That is why it adjusts your ledger, not the statement side.
A16: Hint: the deposit in transit is 2,900.
